<?xml version="1.0" encoding="utf-8"?><testsuite errors="1" failures="0" name="pytest" skips="0" tests="1" time="0.562"><testcase classname="" file="test_main.py" name="test_main" time="0"><error message="collection failure">../../venv/lib/python3.8/site-packages/pluggy/__init__.py:617: in __call__
    return self._hookexec(self, self._nonwrappers + self._wrappers, kwargs)
../../venv/lib/python3.8/site-packages/pluggy/__init__.py:222: in _hookexec
    return self._inner_hookexec(hook, methods, kwargs)
../../venv/lib/python3.8/site-packages/pluggy/__init__.py:214: in &lt;lambda&gt;
    hook.multicall(
../../venv/lib/python3.8/site-packages/_pytest/python.py:240: in pytest_pycollect_makeitem
    res = list(collector._genfunctions(name, obj))
../../venv/lib/python3.8/site-packages/_pytest/python.py:432: in _genfunctions
    self.ihook.pytest_generate_tests(metafunc=metafunc)
../../venv/lib/python3.8/site-packages/pluggy/__init__.py:617: in __call__
    return self._hookexec(self, self._nonwrappers + self._wrappers, kwargs)
../../venv/lib/python3.8/site-packages/pluggy/__init__.py:222: in _hookexec
    return self._inner_hookexec(hook, methods, kwargs)
../../venv/lib/python3.8/site-packages/pluggy/__init__.py:214: in &lt;lambda&gt;
    hook.multicall(
../../venv/lib/python3.8/site-packages/_pytest/python.py:161: in pytest_generate_tests
    metafunc.parametrize(*marker.args, **marker.kwargs)
../../venv/lib/python3.8/site-packages/_pytest/python.py:894: in parametrize
    raise ValueError(&quot;%r uses no %s %r&quot; % (self.function, name, arg))
E   ValueError: &lt;function test_get_temperature_by_lat_lng at 0x7f75f85068b0&gt; uses no argument &apos;expected&apos;</error></testcase></testsuite>